WARNING:werkzeug: * Debugger is active!
INFO:werkzeug: * Debugger PIN: 609-915-266
INFO:werkzeug:127.0.0.1 - - [26/Feb/2024 15:25:16] "OPTIONS /api/v1/admin/createUser HTTP/1.1" 200 -
INFO:werkzeug:127.0.0.1 - - [26/Feb/2024 15:25:16] "[35m[1mPOST /api/v1/admin/createUser HTTP/1.1[0m" 500 -
INFO:werkzeug:127.0.0.1 - - [26/Feb/2024 15:25:33] "OPTIONS /api/v1/admin/createUser HTTP/1.1" 200 -
INFO:werkzeug:127.0.0.1 - - [26/Feb/2024 15:25:33] "[35m[1mPOST /api/v1/admin/createUser HTTP/1.1[0m" 500 -
INFO:werkzeug:127.0.0.1 - - [26/Feb/2024 15:28:26] "GET /api/v1/admin/home HTTP/1.1" 200 -
INFO:werkzeug:127.0.0.1 - - [26/Feb/2024 15:28:53] "GET /api/v1/admin/home HTTP/1.1" 200 -
INFO:werkzeug: * Detected change in '/home/adilmohamedparayil/Desktop/Mini Project/userprofilemanagement-1/backend/app/services/admin.py', reloading
INFO:werkzeug:[31m[1mWARNING: This is a development server. Do not use it in a production deployment. Use a production WSGI server instead.[0m
 * Running on http://127.0.0.1:5000
INFO:werkzeug:[33mPress CTRL+C to quit[0m
INFO:werkzeug: * Restarting with stat
WARNING:werkzeug: * Debugger is active!
INFO:werkzeug: * Debugger PIN: 609-915-266
INFO:werkzeug:127.0.0.1 - - [26/Feb/2024 16:22:20] "OPTIONS /api/v1/login HTTP/1.1" 200 -
INFO:werkzeug:127.0.0.1 - - [26/Feb/2024 16:22:20] "POST /api/v1/login HTTP/1.1" 200 -
INFO:werkzeug:127.0.0.1 - - [26/Feb/2024 16:22:21] "GET /api/v1/admin/home HTTP/1.1" 200 -
ERROR:root:An error occurred:
Traceback (most recent call last):
  File "/home/adilmohamedparayil/.local/lib/python3.8/site-packages/flask/app.py", line 1484, in full_dispatch_request
    rv = self.dispatch_request()
  File "/home/adilmohamedparayil/.local/lib/python3.8/site-packages/flask/app.py", line 1458, in dispatch_request
    self.raise_routing_exception(req)
  File "/home/adilmohamedparayil/.local/lib/python3.8/site-packages/flask/app.py", line 1440, in raise_routing_exception
    raise request.routing_exception  # type: ignore
  File "/home/adilmohamedparayil/.local/lib/python3.8/site-packages/flask/ctx.py", line 353, in match_request
    result = self.url_adapter.match(return_rule=True)  # type: ignore
  File "/home/adilmohamedparayil/.local/lib/python3.8/site-packages/werkzeug/routing/map.py", line 655, in match
    raise NotFound() from None
werkzeug.exceptions.NotFound: 404 Not Found: The requested URL was not found on the server. If you entered the URL manually please check your spelling and try again.
INFO:werkzeug:127.0.0.1 - - [26/Feb/2024 16:22:21] "[33mGET /favicon.ico HTTP/1.1[0m" 404 -
INFO:werkzeug:127.0.0.1 - - [26/Feb/2024 16:22:45] "OPTIONS /api/v1/admin/createUser HTTP/1.1" 200 -
INFO:werkzeug:127.0.0.1 - - [26/Feb/2024 16:22:45] "[35m[1mPOST /api/v1/admin/createUser HTTP/1.1[0m" 500 -
INFO:werkzeug:127.0.0.1 - - [26/Feb/2024 16:26:36] "GET /api/v1/admin/home HTTP/1.1" 200 -
ERROR:root:An error occurred:
Traceback (most recent call last):
  File "/home/adilmohamedparayil/.local/lib/python3.8/site-packages/flask/app.py", line 1484, in full_dispatch_request
    rv = self.dispatch_request()
  File "/home/adilmohamedparayil/.local/lib/python3.8/site-packages/flask/app.py", line 1458, in dispatch_request
    self.raise_routing_exception(req)
  File "/home/adilmohamedparayil/.local/lib/python3.8/site-packages/flask/app.py", line 1440, in raise_routing_exception
    raise request.routing_exception  # type: ignore
  File "/home/adilmohamedparayil/.local/lib/python3.8/site-packages/flask/ctx.py", line 353, in match_request
    result = self.url_adapter.match(return_rule=True)  # type: ignore
  File "/home/adilmohamedparayil/.local/lib/python3.8/site-packages/werkzeug/routing/map.py", line 655, in match
    raise NotFound() from None
werkzeug.exceptions.NotFound: 404 Not Found: The requested URL was not found on the server. If you entered the URL manually please check your spelling and try again.
INFO:werkzeug:127.0.0.1 - - [26/Feb/2024 17:02:59] "[33mGET /favicon.ico HTTP/1.1[0m" 404 -
INFO:werkzeug:127.0.0.1 - - [26/Feb/2024 17:02:59] "GET /api/v1/admin/home HTTP/1.1" 200 -
ERROR:root:An error occurred:
Traceback (most recent call last):
  File "/home/adilmohamedparayil/.local/lib/python3.8/site-packages/flask/app.py", line 1484, in full_dispatch_request
    rv = self.dispatch_request()
  File "/home/adilmohamedparayil/.local/lib/python3.8/site-packages/flask/app.py", line 1458, in dispatch_request
    self.raise_routing_exception(req)
  File "/home/adilmohamedparayil/.local/lib/python3.8/site-packages/flask/app.py", line 1440, in raise_routing_exception
    raise request.routing_exception  # type: ignore
  File "/home/adilmohamedparayil/.local/lib/python3.8/site-packages/flask/ctx.py", line 353, in match_request
    result = self.url_adapter.match(return_rule=True)  # type: ignore
  File "/home/adilmohamedparayil/.local/lib/python3.8/site-packages/werkzeug/routing/map.py", line 655, in match
    raise NotFound() from None
werkzeug.exceptions.NotFound: 404 Not Found: The requested URL was not found on the server. If you entered the URL manually please check your spelling and try again.
INFO:werkzeug:127.0.0.1 - - [26/Feb/2024 17:18:35] "[33mGET /favicon.ico HTTP/1.1[0m" 404 -
INFO:werkzeug:127.0.0.1 - - [26/Feb/2024 17:18:35] "GET /api/v1/admin/home HTTP/1.1" 200 -
INFO:werkzeug:127.0.0.1 - - [26/Feb/2024 17:19:41] "GET /api/v1/admin/home HTTP/1.1" 200 -
ERROR:root:An error occurred:
Traceback (most recent call last):
  File "/home/adilmohamedparayil/.local/lib/python3.8/site-packages/flask/app.py", line 1484, in full_dispatch_request
    rv = self.dispatch_request()
  File "/home/adilmohamedparayil/.local/lib/python3.8/site-packages/flask/app.py", line 1458, in dispatch_request
    self.raise_routing_exception(req)
  File "/home/adilmohamedparayil/.local/lib/python3.8/site-packages/flask/app.py", line 1440, in raise_routing_exception
    raise request.routing_exception  # type: ignore
  File "/home/adilmohamedparayil/.local/lib/python3.8/site-packages/flask/ctx.py", line 353, in match_request
    result = self.url_adapter.match(return_rule=True)  # type: ignore
  File "/home/adilmohamedparayil/.local/lib/python3.8/site-packages/werkzeug/routing/map.py", line 655, in match
    raise NotFound() from None
werkzeug.exceptions.NotFound: 404 Not Found: The requested URL was not found on the server. If you entered the URL manually please check your spelling and try again.
INFO:werkzeug:127.0.0.1 - - [26/Feb/2024 17:24:26] "[33mGET /favicon.ico HTTP/1.1[0m" 404 -
ERROR:root:An error occurred:
Traceback (most recent call last):
  File "/home/adilmohamedparayil/.local/lib/python3.8/site-packages/flask/app.py", line 1484, in full_dispatch_request
    rv = self.dispatch_request()
  File "/home/adilmohamedparayil/.local/lib/python3.8/site-packages/flask/app.py", line 1458, in dispatch_request
    self.raise_routing_exception(req)
  File "/home/adilmohamedparayil/.local/lib/python3.8/site-packages/flask/app.py", line 1440, in raise_routing_exception
    raise request.routing_exception  # type: ignore
  File "/home/adilmohamedparayil/.local/lib/python3.8/site-packages/flask/ctx.py", line 353, in match_request
    result = self.url_adapter.match(return_rule=True)  # type: ignore
  File "/home/adilmohamedparayil/.local/lib/python3.8/site-packages/werkzeug/routing/map.py", line 655, in match
    raise NotFound() from None
werkzeug.exceptions.NotFound: 404 Not Found: The requested URL was not found on the server. If you entered the URL manually please check your spelling and try again.
INFO:werkzeug:127.0.0.1 - - [26/Feb/2024 17:36:27] "[33mGET /favicon.ico HTTP/1.1[0m" 404 -
ERROR:root:An error occurred:
Traceback (most recent call last):
  File "/home/adilmohamedparayil/.local/lib/python3.8/site-packages/flask/app.py", line 1484, in full_dispatch_request
    rv = self.dispatch_request()
  File "/home/adilmohamedparayil/.local/lib/python3.8/site-packages/flask/app.py", line 1458, in dispatch_request
    self.raise_routing_exception(req)
  File "/home/adilmohamedparayil/.local/lib/python3.8/site-packages/flask/app.py", line 1440, in raise_routing_exception
    raise request.routing_exception  # type: ignore
  File "/home/adilmohamedparayil/.local/lib/python3.8/site-packages/flask/ctx.py", line 353, in match_request
    result = self.url_adapter.match(return_rule=True)  # type: ignore
  File "/home/adilmohamedparayil/.local/lib/python3.8/site-packages/werkzeug/routing/map.py", line 655, in match
    raise NotFound() from None
werkzeug.exceptions.NotFound: 404 Not Found: The requested URL was not found on the server. If you entered the URL manually please check your spelling and try again.
INFO:werkzeug:127.0.0.1 - - [26/Feb/2024 17:39:21] "[33mGET /favicon.ico HTTP/1.1[0m" 404 -
ERROR:root:An error occurred:
Traceback (most recent call last):
  File "/home/adilmohamedparayil/.local/lib/python3.8/site-packages/flask/app.py", line 1484, in full_dispatch_request
    rv = self.dispatch_request()
  File "/home/adilmohamedparayil/.local/lib/python3.8/site-packages/flask/app.py", line 1458, in dispatch_request
    self.raise_routing_exception(req)
  File "/home/adilmohamedparayil/.local/lib/python3.8/site-packages/flask/app.py", line 1440, in raise_routing_exception
    raise request.routing_exception  # type: ignore
  File "/home/adilmohamedparayil/.local/lib/python3.8/site-packages/flask/ctx.py", line 353, in match_request
    result = self.url_adapter.match(return_rule=True)  # type: ignore
  File "/home/adilmohamedparayil/.local/lib/python3.8/site-packages/werkzeug/routing/map.py", line 655, in match
    raise NotFound() from None
werkzeug.exceptions.NotFound: 404 Not Found: The requested URL was not found on the server. If you entered the URL manually please check your spelling and try again.
INFO:werkzeug:127.0.0.1 - - [26/Feb/2024 17:39:44] "[33mGET /favicon.ico HTTP/1.1[0m" 404 -
ERROR:root:An error occurred:
Traceback (most recent call last):
  File "/home/adilmohamedparayil/.local/lib/python3.8/site-packages/flask/app.py", line 1484, in full_dispatch_request
    rv = self.dispatch_request()
  File "/home/adilmohamedparayil/.local/lib/python3.8/site-packages/flask/app.py", line 1458, in dispatch_request
    self.raise_routing_exception(req)
  File "/home/adilmohamedparayil/.local/lib/python3.8/site-packages/flask/app.py", line 1440, in raise_routing_exception
    raise request.routing_exception  # type: ignore
  File "/home/adilmohamedparayil/.local/lib/python3.8/site-packages/flask/ctx.py", line 353, in match_request
    result = self.url_adapter.match(return_rule=True)  # type: ignore
  File "/home/adilmohamedparayil/.local/lib/python3.8/site-packages/werkzeug/routing/map.py", line 655, in match
    raise NotFound() from None
werkzeug.exceptions.NotFound: 404 Not Found: The requested URL was not found on the server. If you entered the URL manually please check your spelling and try again.
INFO:werkzeug:127.0.0.1 - - [26/Feb/2024 17:54:06] "[33mGET /favicon.ico HTTP/1.1[0m" 404 -
INFO:werkzeug:127.0.0.1 - - [26/Feb/2024 18:06:34] "OPTIONS /api/v1/admin/removeUser?username=USRX241002 HTTP/1.1" 200 -
ERROR:root:An error occurred:
Traceback (most recent call last):
  File "/home/adilmohamedparayil/.local/lib/python3.8/site-packages/flask/app.py", line 1484, in full_dispatch_request
    rv = self.dispatch_request()
  File "/home/adilmohamedparayil/.local/lib/python3.8/site-packages/flask/app.py", line 1469, in dispatch_request
    return self.ensure_sync(self.view_functions[rule.endpoint])(**view_args)
  File "/home/adilmohamedparayil/Desktop/Mini Project/userprofilemanagement-1/backend/app/controller/admin_controller.py", line 34, in admin_remove_user
    return fun_admin_delete_user()
  File "/home/adilmohamedparayil/Desktop/Mini Project/userprofilemanagement-1/backend/app/services/admin.py", line 320, in fun_admin_delete_user
    role_type = cursor.fetchone()[0]
TypeError: 'NoneType' object is not subscriptable
INFO:werkzeug:127.0.0.1 - - [26/Feb/2024 18:06:34] "[35m[1mDELETE /api/v1/admin/removeUser?username=USRX241002 HTTP/1.1[0m" 500 -
INFO:werkzeug:127.0.0.1 - - [26/Feb/2024 18:08:29] "OPTIONS /api/v1/admin/removeUser?username= HTTP/1.1" 200 -
ERROR:root:An error occurred:
Traceback (most recent call last):
  File "/home/adilmohamedparayil/.local/lib/python3.8/site-packages/flask/app.py", line 1484, in full_dispatch_request
    rv = self.dispatch_request()
  File "/home/adilmohamedparayil/.local/lib/python3.8/site-packages/flask/app.py", line 1469, in dispatch_request
    return self.ensure_sync(self.view_functions[rule.endpoint])(**view_args)
  File "/home/adilmohamedparayil/Desktop/Mini Project/userprofilemanagement-1/backend/app/controller/admin_controller.py", line 34, in admin_remove_user
    return fun_admin_delete_user()
  File "/home/adilmohamedparayil/Desktop/Mini Project/userprofilemanagement-1/backend/app/services/admin.py", line 320, in fun_admin_delete_user
    role_type = cursor.fetchone()[0]
TypeError: 'NoneType' object is not subscriptable
INFO:werkzeug:127.0.0.1 - - [26/Feb/2024 18:08:29] "[35m[1mDELETE /api/v1/admin/removeUser?username= HTTP/1.1[0m" 500 -
INFO:werkzeug:127.0.0.1 - - [26/Feb/2024 18:10:07] "OPTIONS /api/v1/admin/removeUser?username= HTTP/1.1" 200 -
ERROR:root:An error occurred:
Traceback (most recent call last):
  File "/home/adilmohamedparayil/.local/lib/python3.8/site-packages/flask/app.py", line 1484, in full_dispatch_request
    rv = self.dispatch_request()
  File "/home/adilmohamedparayil/.local/lib/python3.8/site-packages/flask/app.py", line 1469, in dispatch_request
    return self.ensure_sync(self.view_functions[rule.endpoint])(**view_args)
  File "/home/adilmohamedparayil/Desktop/Mini Project/userprofilemanagement-1/backend/app/controller/admin_controller.py", line 34, in admin_remove_user
    return fun_admin_delete_user()
  File "/home/adilmohamedparayil/Desktop/Mini Project/userprofilemanagement-1/backend/app/services/admin.py", line 320, in fun_admin_delete_user
    role_type = cursor.fetchone()[0]
TypeError: 'NoneType' object is not subscriptable
INFO:werkzeug:127.0.0.1 - - [26/Feb/2024 18:10:07] "[35m[1mDELETE /api/v1/admin/removeUser?username= HTTP/1.1[0m" 500 -
INFO:werkzeug:127.0.0.1 - - [26/Feb/2024 18:10:29] "OPTIONS /api/v1/admin/removeUser?username= HTTP/1.1" 200 -
ERROR:root:An error occurred:
Traceback (most recent call last):
  File "/home/adilmohamedparayil/.local/lib/python3.8/site-packages/flask/app.py", line 1484, in full_dispatch_request
    rv = self.dispatch_request()
  File "/home/adilmohamedparayil/.local/lib/python3.8/site-packages/flask/app.py", line 1469, in dispatch_request
    return self.ensure_sync(self.view_functions[rule.endpoint])(**view_args)
  File "/home/adilmohamedparayil/Desktop/Mini Project/userprofilemanagement-1/backend/app/controller/admin_controller.py", line 34, in admin_remove_user
    return fun_admin_delete_user()
  File "/home/adilmohamedparayil/Desktop/Mini Project/userprofilemanagement-1/backend/app/services/admin.py", line 320, in fun_admin_delete_user
    role_type = cursor.fetchone()[0]
TypeError: 'NoneType' object is not subscriptable
INFO:werkzeug:127.0.0.1 - - [26/Feb/2024 18:10:29] "[35m[1mDELETE /api/v1/admin/removeUser?username= HTTP/1.1[0m" 500 -
INFO:werkzeug:127.0.0.1 - - [26/Feb/2024 18:13:40] "OPTIONS /api/v1/admin/removeUser?username= HTTP/1.1" 200 -
ERROR:root:An error occurred:
Traceback (most recent call last):
  File "/home/adilmohamedparayil/.local/lib/python3.8/site-packages/flask/app.py", line 1484, in full_dispatch_request
    rv = self.dispatch_request()
  File "/home/adilmohamedparayil/.local/lib/python3.8/site-packages/flask/app.py", line 1469, in dispatch_request
    return self.ensure_sync(self.view_functions[rule.endpoint])(**view_args)
  File "/home/adilmohamedparayil/Desktop/Mini Project/userprofilemanagement-1/backend/app/controller/admin_controller.py", line 34, in admin_remove_user
    return fun_admin_delete_user()
  File "/home/adilmohamedparayil/Desktop/Mini Project/userprofilemanagement-1/backend/app/services/admin.py", line 320, in fun_admin_delete_user
    role_type = cursor.fetchone()[0]
TypeError: 'NoneType' object is not subscriptable
INFO:werkzeug:127.0.0.1 - - [26/Feb/2024 18:13:40] "[35m[1mDELETE /api/v1/admin/removeUser?username= HTTP/1.1[0m" 500 -
ERROR:root:An error occurred:
Traceback (most recent call last):
  File "/home/adilmohamedparayil/.local/lib/python3.8/site-packages/flask/app.py", line 1484, in full_dispatch_request
    rv = self.dispatch_request()
  File "/home/adilmohamedparayil/.local/lib/python3.8/site-packages/flask/app.py", line 1469, in dispatch_request
    return self.ensure_sync(self.view_functions[rule.endpoint])(**view_args)
  File "/home/adilmohamedparayil/Desktop/Mini Project/userprofilemanagement-1/backend/app/controller/admin_controller.py", line 34, in admin_remove_user
    return fun_admin_delete_user()
  File "/home/adilmohamedparayil/Desktop/Mini Project/userprofilemanagement-1/backend/app/services/admin.py", line 320, in fun_admin_delete_user
    role_type = cursor.fetchone()[0]
TypeError: 'NoneType' object is not subscriptable
INFO:werkzeug:127.0.0.1 - - [26/Feb/2024 18:13:43] "[35m[1mDELETE /api/v1/admin/removeUser?username= HTTP/1.1[0m" 500 -
INFO:werkzeug:127.0.0.1 - - [26/Feb/2024 20:47:16] "OPTIONS /api/v1/admin/removeUser?username= HTTP/1.1" 200 -
ERROR:root:An error occurred:
Traceback (most recent call last):
  File "/home/adilmohamedparayil/.local/lib/python3.8/site-packages/flask/app.py", line 1484, in full_dispatch_request
    rv = self.dispatch_request()
  File "/home/adilmohamedparayil/.local/lib/python3.8/site-packages/flask/app.py", line 1469, in dispatch_request
    return self.ensure_sync(self.view_functions[rule.endpoint])(**view_args)
  File "/home/adilmohamedparayil/Desktop/Mini Project/userprofilemanagement-1/backend/app/controller/admin_controller.py", line 34, in admin_remove_user
    return fun_admin_delete_user()
  File "/home/adilmohamedparayil/Desktop/Mini Project/userprofilemanagement-1/backend/app/services/admin.py", line 320, in fun_admin_delete_user
    role_type = cursor.fetchone()[0]
TypeError: 'NoneType' object is not subscriptable
INFO:werkzeug:127.0.0.1 - - [26/Feb/2024 20:47:16] "[35m[1mDELETE /api/v1/admin/removeUser?username= HTTP/1.1[0m" 500 -
INFO:werkzeug:127.0.0.1 - - [26/Feb/2024 20:47:22] "GET /api/v1/admin/home HTTP/1.1" 200 -
INFO:werkzeug:127.0.0.1 - - [26/Feb/2024 20:49:11] "GET /api/v1/admin/home HTTP/1.1" 200 -
INFO:werkzeug:127.0.0.1 - - [26/Feb/2024 21:09:40] "GET /api/v1/admin/home HTTP/1.1" 200 -
INFO:werkzeug:127.0.0.1 - - [26/Feb/2024 21:11:31] "GET /api/v1/admin/home HTTP/1.1" 200 -
INFO:werkzeug:127.0.0.1 - - [26/Feb/2024 21:31:23] "GET /api/v1/admin/home HTTP/1.1" 200 -
INFO:werkzeug:127.0.0.1 - - [26/Feb/2024 21:32:11] "GET /api/v1/admin/home HTTP/1.1" 200 -
INFO:werkzeug:127.0.0.1 - - [26/Feb/2024 21:35:50] "GET /api/v1/admin/home HTTP/1.1" 200 -
INFO:werkzeug:127.0.0.1 - - [26/Feb/2024 21:35:54] "GET /api/v1/admin/home HTTP/1.1" 200 -
INFO:werkzeug:127.0.0.1 - - [26/Feb/2024 21:35:57] "GET /api/v1/admin/home HTTP/1.1" 200 -
ERROR:root:An error occurred:
Traceback (most recent call last):
  File "/home/adilmohamedparayil/.local/lib/python3.8/site-packages/flask/app.py", line 1484, in full_dispatch_request
    rv = self.dispatch_request()
  File "/home/adilmohamedparayil/.local/lib/python3.8/site-packages/flask/app.py", line 1458, in dispatch_request
    self.raise_routing_exception(req)
  File "/home/adilmohamedparayil/.local/lib/python3.8/site-packages/flask/app.py", line 1440, in raise_routing_exception
    raise request.routing_exception  # type: ignore
  File "/home/adilmohamedparayil/.local/lib/python3.8/site-packages/flask/ctx.py", line 353, in match_request
    result = self.url_adapter.match(return_rule=True)  # type: ignore
  File "/home/adilmohamedparayil/.local/lib/python3.8/site-packages/werkzeug/routing/map.py", line 655, in match
    raise NotFound() from None
werkzeug.exceptions.NotFound: 404 Not Found: The requested URL was not found on the server. If you entered the URL manually please check your spelling and try again.
INFO:werkzeug:127.0.0.1 - - [26/Feb/2024 21:47:40] "[33mGET /favicon.ico HTTP/1.1[0m" 404 -
INFO:werkzeug:127.0.0.1 - - [26/Feb/2024 22:01:57] "GET /api/v1/admin/home HTTP/1.1" 200 -
INFO:werkzeug:127.0.0.1 - - [26/Feb/2024 22:19:50] "GET /api/v1/admin/home HTTP/1.1" 200 -
INFO:werkzeug:127.0.0.1 - - [26/Feb/2024 22:21:24] "GET /api/v1/admin/home HTTP/1.1" 200 -
ERROR:root:An error occurred:
Traceback (most recent call last):
  File "/home/adilmohamedparayil/.local/lib/python3.8/site-packages/flask/app.py", line 1484, in full_dispatch_request
    rv = self.dispatch_request()
  File "/home/adilmohamedparayil/.local/lib/python3.8/site-packages/flask/app.py", line 1458, in dispatch_request
    self.raise_routing_exception(req)
  File "/home/adilmohamedparayil/.local/lib/python3.8/site-packages/flask/app.py", line 1440, in raise_routing_exception
    raise request.routing_exception  # type: ignore
  File "/home/adilmohamedparayil/.local/lib/python3.8/site-packages/flask/ctx.py", line 353, in match_request
    result = self.url_adapter.match(return_rule=True)  # type: ignore
  File "/home/adilmohamedparayil/.local/lib/python3.8/site-packages/werkzeug/routing/map.py", line 655, in match
    raise NotFound() from None
werkzeug.exceptions.NotFound: 404 Not Found: The requested URL was not found on the server. If you entered the URL manually please check your spelling and try again.
INFO:werkzeug:127.0.0.1 - - [26/Feb/2024 22:26:50] "[33mGET /favicon.ico HTTP/1.1[0m" 404 -
ERROR:root:An error occurred:
Traceback (most recent call last):
  File "/home/adilmohamedparayil/.local/lib/python3.8/site-packages/flask/app.py", line 1484, in full_dispatch_request
    rv = self.dispatch_request()
  File "/home/adilmohamedparayil/.local/lib/python3.8/site-packages/flask/app.py", line 1458, in dispatch_request
    self.raise_routing_exception(req)
  File "/home/adilmohamedparayil/.local/lib/python3.8/site-packages/flask/app.py", line 1440, in raise_routing_exception
    raise request.routing_exception  # type: ignore
  File "/home/adilmohamedparayil/.local/lib/python3.8/site-packages/flask/ctx.py", line 353, in match_request
    result = self.url_adapter.match(return_rule=True)  # type: ignore
  File "/home/adilmohamedparayil/.local/lib/python3.8/site-packages/werkzeug/routing/map.py", line 655, in match
    raise NotFound() from None
werkzeug.exceptions.NotFound: 404 Not Found: The requested URL was not found on the server. If you entered the URL manually please check your spelling and try again.
INFO:werkzeug:127.0.0.1 - - [26/Feb/2024 22:27:01] "[33mGET /favicon.ico HTTP/1.1[0m" 404 -
ERROR:root:An error occurred:
Traceback (most recent call last):
  File "/home/adilmohamedparayil/.local/lib/python3.8/site-packages/flask/app.py", line 1484, in full_dispatch_request
    rv = self.dispatch_request()
  File "/home/adilmohamedparayil/.local/lib/python3.8/site-packages/flask/app.py", line 1458, in dispatch_request
    self.raise_routing_exception(req)
  File "/home/adilmohamedparayil/.local/lib/python3.8/site-packages/flask/app.py", line 1440, in raise_routing_exception
    raise request.routing_exception  # type: ignore
  File "/home/adilmohamedparayil/.local/lib/python3.8/site-packages/flask/ctx.py", line 353, in match_request
    result = self.url_adapter.match(return_rule=True)  # type: ignore
  File "/home/adilmohamedparayil/.local/lib/python3.8/site-packages/werkzeug/routing/map.py", line 655, in match
    raise NotFound() from None
werkzeug.exceptions.NotFound: 404 Not Found: The requested URL was not found on the server. If you entered the URL manually please check your spelling and try again.
INFO:werkzeug:127.0.0.1 - - [26/Feb/2024 22:27:12] "[33mGET /favicon.ico HTTP/1.1[0m" 404 -
INFO:werkzeug:127.0.0.1 - - [26/Feb/2024 22:28:01] "GET /api/v1/admin/home HTTP/1.1" 200 -
INFO:werkzeug:127.0.0.1 - - [26/Feb/2024 22:29:29] "GET /api/v1/admin/home HTTP/1.1" 200 -
INFO:werkzeug:127.0.0.1 - - [26/Feb/2024 22:29:46] "GET /api/v1/admin/home HTTP/1.1" 200 -
INFO:werkzeug:127.0.0.1 - - [26/Feb/2024 22:30:32] "GET /api/v1/admin/home HTTP/1.1" 200 -
INFO:werkzeug:127.0.0.1 - - [26/Feb/2024 22:51:28] "GET /api/v1/admin/home HTTP/1.1" 200 -
INFO:werkzeug:127.0.0.1 - - [26/Feb/2024 22:54:17] "GET /api/v1/admin/home HTTP/1.1" 200 -
INFO:werkzeug:127.0.0.1 - - [26/Feb/2024 22:54:32] "GET /api/v1/admin/home HTTP/1.1" 200 -
INFO:werkzeug:127.0.0.1 - - [26/Feb/2024 22:55:15] "GET /api/v1/admin/home HTTP/1.1" 200 -
INFO:werkzeug:127.0.0.1 - - [26/Feb/2024 23:01:45] "GET /api/v1/admin/home HTTP/1.1" 200 -
INFO:werkzeug:127.0.0.1 - - [26/Feb/2024 23:02:56] "GET /api/v1/admin/home HTTP/1.1" 200 -
INFO:werkzeug:127.0.0.1 - - [26/Feb/2024 23:03:00] "GET /api/v1/admin/home HTTP/1.1" 200 -
INFO:werkzeug:127.0.0.1 - - [26/Feb/2024 23:17:32] "GET /api/v1/admin/home HTTP/1.1" 200 -
INFO:werkzeug:[31m[1mWARNING: This is a development server. Do not use it in a production deployment. Use a production WSGI server instead.[0m
 * Running on http://127.0.0.1:5000
INFO:werkzeug:[33mPress CTRL+C to quit[0m
INFO:werkzeug: * Restarting with stat
WARNING:werkzeug: * Debugger is active!
INFO:werkzeug: * Debugger PIN: 824-670-270
INFO:werkzeug:127.0.0.1 - - [27/Feb/2024 09:10:11] "OPTIONS /api/v1/login HTTP/1.1" 200 -
INFO:werkzeug:127.0.0.1 - - [27/Feb/2024 09:10:12] "POST /api/v1/login HTTP/1.1" 200 -
INFO:werkzeug:127.0.0.1 - - [27/Feb/2024 09:10:12] "GET /api/v1/admin/home HTTP/1.1" 200 -
INFO:werkzeug:127.0.0.1 - - [27/Feb/2024 09:16:06] "GET /api/v1/admin/home HTTP/1.1" 200 -
INFO:werkzeug:127.0.0.1 - - [27/Feb/2024 09:21:27] "GET /api/v1/admin/home HTTP/1.1" 200 -
INFO:werkzeug:127.0.0.1 - - [27/Feb/2024 09:26:41] "GET /api/v1/admin/home HTTP/1.1" 200 -
INFO:werkzeug:127.0.0.1 - - [27/Feb/2024 09:26:50] "GET /api/v1/admin/home HTTP/1.1" 200 -
INFO:werkzeug:127.0.0.1 - - [27/Feb/2024 09:27:28] "GET /api/v1/admin/home HTTP/1.1" 200 -
INFO:werkzeug:127.0.0.1 - - [27/Feb/2024 09:33:01] "GET /api/v1/admin/home HTTP/1.1" 200 -
INFO:werkzeug:127.0.0.1 - - [27/Feb/2024 09:38:56] "GET /api/v1/admin/home HTTP/1.1" 200 -
INFO:werkzeug:127.0.0.1 - - [27/Feb/2024 09:41:00] "GET /api/v1/admin/home HTTP/1.1" 200 -
INFO:werkzeug:127.0.0.1 - - [27/Feb/2024 09:41:48] "GET /api/v1/admin/home HTTP/1.1" 200 -
INFO:werkzeug:127.0.0.1 - - [27/Feb/2024 09:51:40] "GET /api/v1/admin/home HTTP/1.1" 200 -
INFO:werkzeug:127.0.0.1 - - [27/Feb/2024 10:14:52] "GET /api/v1/admin/home HTTP/1.1" 200 -
ERROR:root:An error occurred:
Traceback (most recent call last):
  File "/home/adilmohamedparayil/.local/lib/python3.8/site-packages/flask/app.py", line 1484, in full_dispatch_request
    rv = self.dispatch_request()
  File "/home/adilmohamedparayil/.local/lib/python3.8/site-packages/flask/app.py", line 1458, in dispatch_request
    self.raise_routing_exception(req)
  File "/home/adilmohamedparayil/.local/lib/python3.8/site-packages/flask/app.py", line 1440, in raise_routing_exception
    raise request.routing_exception  # type: ignore
  File "/home/adilmohamedparayil/.local/lib/python3.8/site-packages/flask/ctx.py", line 353, in match_request
    result = self.url_adapter.match(return_rule=True)  # type: ignore
  File "/home/adilmohamedparayil/.local/lib/python3.8/site-packages/werkzeug/routing/map.py", line 655, in match
    raise NotFound() from None
werkzeug.exceptions.NotFound: 404 Not Found: The requested URL was not found on the server. If you entered the URL manually please check your spelling and try again.
INFO:werkzeug:127.0.0.1 - - [27/Feb/2024 10:16:18] "[33mGET /favicon.ico HTTP/1.1[0m" 404 -
INFO:werkzeug:127.0.0.1 - - [27/Feb/2024 10:21:37] "GET /api/v1/admin/home HTTP/1.1" 200 -
INFO:werkzeug:127.0.0.1 - - [27/Feb/2024 10:25:36] "GET /api/v1/admin/home HTTP/1.1" 200 -
